Traceback (most recent call last):
  File "c:\users\lloyd\anaconda3\envs\dscore\lib\site-packages\jupyter_cache\executors\utils.py", line 56, in single_nb_execution
    record_timing=False,
  File "c:\users\lloyd\anaconda3\envs\dscore\lib\site-packages\nbclient\client.py", line 1082, in execute
    return NotebookClient(nb=nb, resources=resources, km=km, **kwargs).execute()
  File "c:\users\lloyd\anaconda3\envs\dscore\lib\site-packages\nbclient\util.py", line 74, in wrapped
    return just_run(coro(*args, **kwargs))
  File "c:\users\lloyd\anaconda3\envs\dscore\lib\site-packages\nbclient\util.py", line 53, in just_run
    return loop.run_until_complete(coro)
  File "c:\users\lloyd\anaconda3\envs\dscore\lib\asyncio\base_events.py", line 587, in run_until_complete
    return future.result()
  File "c:\users\lloyd\anaconda3\envs\dscore\lib\site-packages\nbclient\client.py", line 536, in async_execute
    cell, index, execution_count=self.code_cells_executed + 1
  File "c:\users\lloyd\anaconda3\envs\dscore\lib\site-packages\nbclient\client.py", line 827, in async_execute_cell
    self._check_raise_for_error(cell, exec_reply)
  File "c:\users\lloyd\anaconda3\envs\dscore\lib\site-packages\nbclient\client.py", line 735, in _check_raise_for_error
    raise CellExecutionError.from_cell_and_msg(cell, exec_reply['content'])
nbclient.exceptions.CellExecutionError: An error occurred while executing the following cell:
------------------
%matplotlib inline

from collections import Counter
from itertools import filterfalse
from numbers import Number

import matplotlib as mpl
import matplotlib.pyplot as plt
import numpy as np
import pandas as pd
import seaborn as sns
from IPython.display import HTML, display_html
from mpl_toolkits.axes_grid1.inset_locator import inset_axes
from scipy.ndimage import label
from scipy.optimize import fmin
from scipy.stats import chisquare, norm
from tqdm import tqdm, trange

# Homogenise matplotlib plotting.
mpl.rc("axes", grid=True)
mpl.rc("grid", linestyle="--", alpha=0.4)
mpl.rc("legend", loc="best")
------------------

[1;31m---------------------------------------------------------------------------[0m
[1;31mModuleNotFoundError[0m                       Traceback (most recent call last)
[1;32m<ipython-input-1-5a2d40a99a9e>[0m in [0;36m<module>[1;34m[0m
[0;32m     15[0m [1;32mfrom[0m [0mscipy[0m[1;33m.[0m[0moptimize[0m [1;32mimport[0m [0mfmin[0m[1;33m[0m[1;33m[0m[0m
[0;32m     16[0m [1;32mfrom[0m [0mscipy[0m[1;33m.[0m[0mstats[0m [1;32mimport[0m [0mchisquare[0m[1;33m,[0m [0mnorm[0m[1;33m[0m[1;33m[0m[0m
[1;32m---> 17[1;33m [1;32mfrom[0m [0mtqdm[0m [1;32mimport[0m [0mtqdm[0m[1;33m,[0m [0mtrange[0m[1;33m[0m[1;33m[0m[0m
[0m[0;32m     18[0m [1;33m[0m[0m
[0;32m     19[0m [1;31m# Homogenise matplotlib plotting.[0m[1;33m[0m[1;33m[0m[1;33m[0m[0m

[1;31mModuleNotFoundError[0m: No module named 'tqdm'
ModuleNotFoundError: No module named 'tqdm'

